ERROR 2025-03-28 09:52:16,407 log 1 140239606053688 Internal Server Error: /tournament/create/
Traceback (most recent call last):
  File "/usr/local/lib/python3.10/site-packages/django/db/backends/utils.py", line 89, in _execute
    return self.cursor.execute(sql, params)
psycopg2.errors.UndefinedColumn: column "score_limit" of relation "tournament_tournament" does not exist
LINE 1: ...ent_tournament" ("name", "num_players", "winner", "score_lim...
                                                             ^


The above exception was the direct cause of the following exception:

Traceback (most recent call last):
  File "/usr/local/lib/python3.10/site-packages/asgiref/sync.py", line 518, in thread_handler
    raise exc_info[1]
  File "/usr/local/lib/python3.10/site-packages/django/core/handlers/exception.py", line 42, in inner
    response = await get_response(request)
  File "/usr/local/lib/python3.10/site-packages/django/core/handlers/base.py", line 253, in _get_response_async
    response = await wrapped_callback(
  File "/usr/local/lib/python3.10/site-packages/asgiref/sync.py", line 468, in __call__
    ret = await asyncio.shield(exec_coro)
  File "/usr/local/lib/python3.10/site-packages/asgiref/current_thread_executor.py", line 40, in run
    result = self.fn(*self.args, **self.kwargs)
  File "/usr/local/lib/python3.10/site-packages/asgiref/sync.py", line 522, in thread_handler
    return func(*args, **kwargs)
  File "/usr/local/lib/python3.10/site-packages/django/views/decorators/csrf.py", line 56, in wrapper_view
    return view_func(*args, **kwargs)
  File "/app/./tournament/views.py", line 26, in create_tournament
    tournament = Tournament.objects.create(
  File "/usr/local/lib/python3.10/site-packages/django/db/models/manager.py", line 87, in manager_method
    return getattr(self.get_queryset(), name)(*args, **kwargs)
  File "/usr/local/lib/python3.10/site-packages/django/db/models/query.py", line 658, in create
    obj.save(force_insert=True, using=self.db)
  File "/usr/local/lib/python3.10/site-packages/django/db/models/base.py", line 814, in save
    self.save_base(
  File "/usr/local/lib/python3.10/site-packages/django/db/models/base.py", line 877, in save_base
    updated = self._save_table(
  File "/usr/local/lib/python3.10/site-packages/django/db/models/base.py", line 1020, in _save_table
    results = self._do_insert(
  File "/usr/local/lib/python3.10/site-packages/django/db/models/base.py", line 1061, in _do_insert
    return manager._insert(
  File "/usr/local/lib/python3.10/site-packages/django/db/models/manager.py", line 87, in manager_method
    return getattr(self.get_queryset(), name)(*args, **kwargs)
  File "/usr/local/lib/python3.10/site-packages/django/db/models/query.py", line 1805, in _insert
    return query.get_compiler(using=using).execute_sql(returning_fields)
  File "/usr/local/lib/python3.10/site-packages/django/db/models/sql/compiler.py", line 1820, in execute_sql
    cursor.execute(sql, params)
  File "/usr/local/lib/python3.10/site-packages/django/db/backends/utils.py", line 102, in execute
    return super().execute(sql, params)
  File "/usr/local/lib/python3.10/site-packages/django/db/backends/utils.py", line 67, in execute
    return self._execute_with_wrappers(
  File "/usr/local/lib/python3.10/site-packages/django/db/backends/utils.py", line 80, in _execute_with_wrappers
    return executor(sql, params, many, context)
  File "/usr/local/lib/python3.10/site-packages/django/db/backends/utils.py", line 84, in _execute
    with self.db.wrap_database_errors:
  File "/usr/local/lib/python3.10/site-packages/django/db/utils.py", line 91, in __exit__
    raise dj_exc_value.with_traceback(traceback) from exc_value
  File "/usr/local/lib/python3.10/site-packages/django/db/backends/utils.py", line 89, in _execute
    return self.cursor.execute(sql, params)
django.db.utils.ProgrammingError: column "score_limit" of relation "tournament_tournament" does not exist
LINE 1: ...ent_tournament" ("name", "num_players", "winner", "score_lim...
                                                             ^

ERROR 2025-03-28 09:57:26,675 log 1 140035778386744 Internal Server Error: /tournament/create/
Traceback (most recent call last):
  File "/usr/local/lib/python3.10/site-packages/django/db/backends/utils.py", line 89, in _execute
    return self.cursor.execute(sql, params)
psycopg2.errors.UndefinedColumn: column "score_limit" of relation "tournament_tournament" does not exist
LINE 1: ...ent_tournament" ("name", "num_players", "winner", "score_lim...
                                                             ^


The above exception was the direct cause of the following exception:

Traceback (most recent call last):
  File "/usr/local/lib/python3.10/site-packages/asgiref/sync.py", line 518, in thread_handler
    raise exc_info[1]
  File "/usr/local/lib/python3.10/site-packages/django/core/handlers/exception.py", line 42, in inner
    response = await get_response(request)
  File "/usr/local/lib/python3.10/site-packages/django/core/handlers/base.py", line 253, in _get_response_async
    response = await wrapped_callback(
  File "/usr/local/lib/python3.10/site-packages/asgiref/sync.py", line 468, in __call__
    ret = await asyncio.shield(exec_coro)
  File "/usr/local/lib/python3.10/site-packages/asgiref/current_thread_executor.py", line 40, in run
    result = self.fn(*self.args, **self.kwargs)
  File "/usr/local/lib/python3.10/site-packages/asgiref/sync.py", line 522, in thread_handler
    return func(*args, **kwargs)
  File "/usr/local/lib/python3.10/site-packages/django/views/decorators/csrf.py", line 56, in wrapper_view
    return view_func(*args, **kwargs)
  File "/app/./tournament/views.py", line 26, in create_tournament
    tournament = Tournament.objects.create(
  File "/usr/local/lib/python3.10/site-packages/django/db/models/manager.py", line 87, in manager_method
    return getattr(self.get_queryset(), name)(*args, **kwargs)
  File "/usr/local/lib/python3.10/site-packages/django/db/models/query.py", line 658, in create
    obj.save(force_insert=True, using=self.db)
  File "/usr/local/lib/python3.10/site-packages/django/db/models/base.py", line 814, in save
    self.save_base(
  File "/usr/local/lib/python3.10/site-packages/django/db/models/base.py", line 877, in save_base
    updated = self._save_table(
  File "/usr/local/lib/python3.10/site-packages/django/db/models/base.py", line 1020, in _save_table
    results = self._do_insert(
  File "/usr/local/lib/python3.10/site-packages/django/db/models/base.py", line 1061, in _do_insert
    return manager._insert(
  File "/usr/local/lib/python3.10/site-packages/django/db/models/manager.py", line 87, in manager_method
    return getattr(self.get_queryset(), name)(*args, **kwargs)
  File "/usr/local/lib/python3.10/site-packages/django/db/models/query.py", line 1805, in _insert
    return query.get_compiler(using=using).execute_sql(returning_fields)
  File "/usr/local/lib/python3.10/site-packages/django/db/models/sql/compiler.py", line 1820, in execute_sql
    cursor.execute(sql, params)
  File "/usr/local/lib/python3.10/site-packages/django/db/backends/utils.py", line 102, in execute
    return super().execute(sql, params)
  File "/usr/local/lib/python3.10/site-packages/django/db/backends/utils.py", line 67, in execute
    return self._execute_with_wrappers(
  File "/usr/local/lib/python3.10/site-packages/django/db/backends/utils.py", line 80, in _execute_with_wrappers
    return executor(sql, params, many, context)
  File "/usr/local/lib/python3.10/site-packages/django/db/backends/utils.py", line 84, in _execute
    with self.db.wrap_database_errors:
  File "/usr/local/lib/python3.10/site-packages/django/db/utils.py", line 91, in __exit__
    raise dj_exc_value.with_traceback(traceback) from exc_value
  File "/usr/local/lib/python3.10/site-packages/django/db/backends/utils.py", line 89, in _execute
    return self.cursor.execute(sql, params)
django.db.utils.ProgrammingError: column "score_limit" of relation "tournament_tournament" does not exist
LINE 1: ...ent_tournament" ("name", "num_players", "winner", "score_lim...
                                                             ^

ERROR 2025-03-28 10:45:44,371 log 1 140117114391352 Internal Server Error: /tournament/create/
Traceback (most recent call last):
  File "/usr/local/lib/python3.10/site-packages/asgiref/sync.py", line 518, in thread_handler
    raise exc_info[1]
  File "/usr/local/lib/python3.10/site-packages/django/core/handlers/exception.py", line 42, in inner
    response = await get_response(request)
  File "/usr/local/lib/python3.10/site-packages/django/core/handlers/base.py", line 253, in _get_response_async
    response = await wrapped_callback(
  File "/usr/local/lib/python3.10/site-packages/asgiref/sync.py", line 468, in __call__
    ret = await asyncio.shield(exec_coro)
  File "/usr/local/lib/python3.10/site-packages/asgiref/current_thread_executor.py", line 40, in run
    result = self.fn(*self.args, **self.kwargs)
  File "/usr/local/lib/python3.10/site-packages/asgiref/sync.py", line 522, in thread_handler
    return func(*args, **kwargs)
  File "/usr/local/lib/python3.10/site-packages/django/views/decorators/csrf.py", line 56, in wrapper_view
    return view_func(*args, **kwargs)
  File "/app/./tournament/views.py", line 14, in create_tournament
    num_players = int(data.get("num_players"))
TypeError: int() argument must be a string, a bytes-like object or a real number, not 'NoneType'
ERROR 2025-03-28 10:47:11,904 log 1 140117114391352 Internal Server Error: /tournament/create/
Traceback (most recent call last):
  File "/usr/local/lib/python3.10/site-packages/asgiref/sync.py", line 518, in thread_handler
    raise exc_info[1]
  File "/usr/local/lib/python3.10/site-packages/django/core/handlers/exception.py", line 42, in inner
    response = await get_response(request)
  File "/usr/local/lib/python3.10/site-packages/django/core/handlers/base.py", line 253, in _get_response_async
    response = await wrapped_callback(
  File "/usr/local/lib/python3.10/site-packages/asgiref/sync.py", line 468, in __call__
    ret = await asyncio.shield(exec_coro)
  File "/usr/local/lib/python3.10/site-packages/asgiref/current_thread_executor.py", line 40, in run
    result = self.fn(*self.args, **self.kwargs)
  File "/usr/local/lib/python3.10/site-packages/asgiref/sync.py", line 522, in thread_handler
    return func(*args, **kwargs)
  File "/usr/local/lib/python3.10/site-packages/django/views/decorators/csrf.py", line 56, in wrapper_view
    return view_func(*args, **kwargs)
  File "/app/./tournament/views.py", line 14, in create_tournament
    num_players = int(data.get("num_players"))
TypeError: int() argument must be a string, a bytes-like object or a real number, not 'NoneType'
WARNING 2025-03-28 12:27:43,437 log 1 140184401345336 Bad Request: /tournament/1/match/1/finish/
WARNING 2025-03-28 12:47:51,628 log 1 140402055445304 Bad Request: /tournament/37/match/46/finish/
WARNING 2025-03-28 13:15:59,299 log 1 140402055445304 Bad Request: /tournament/37/match/46/finish/
WARNING 2025-03-28 13:28:46,953 log 1 140115468991288 Bad Request: /tournament/38/match/55/finish/
WARNING 2025-03-28 13:43:58,230 log 1 140641825602360 Bad Request: /tournament/42/match/66/finish/
WARNING 2025-03-28 13:44:05,821 log 1 140641825602360 Bad Request: /tournament/42/match/66/finish/
WARNING 2025-03-28 13:50:12,400 log 1 139719942064952 Bad Request: /tournament/43/match/69/finish/
WARNING 2025-03-28 13:50:17,808 log 1 139719942064952 Bad Request: /tournament/43/match/69/finish/
WARNING 2025-03-28 13:50:26,551 log 1 139719942064952 Bad Request: /tournament/43/match/69/finish/
WARNING 2025-03-28 14:20:24,003 log 1 140637766646584 Not Found: /tournament/get_current_id/
WARNING 2025-03-28 14:22:19,059 log 1 140208776371000 Not Found: /tournament/get_current_id/
WARNING 2025-03-28 14:22:21,870 log 1 140208776371000 Not Found: /tournament/get_current_id/
WARNING 2025-03-28 14:22:23,616 log 1 140208776371000 Not Found: /tournament/get_current_id/
WARNING 2025-03-28 14:22:39,643 log 1 140208776371000 Not Found: /tournament/get_current_id/
WARNING 2025-03-28 14:24:09,790 log 1 140208776371000 Not Found: /tournament/get_current_id/
WARNING 2025-03-28 14:26:21,727 log 1 140432729361208 Not Found: /tournament/get_current_id/
WARNING 2025-03-28 14:34:02,430 log 1 140432729361208 Not Found: /tournament/get_current_id/
WARNING 2025-03-28 14:46:29,105 log 1 140622878882616 Not Found: /tournament/get_current_id/
WARNING 2025-03-28 14:46:51,150 log 1 140622878882616 Not Found: /tournament/get_current_id/
WARNING 2025-03-28 14:54:08,206 log 1 140636685114168 Not Found: /tournament/get_current_id/
WARNING 2025-03-28 14:57:54,144 log 1 140636685114168 Not Found: /tournament/get_current_id/
WARNING 2025-03-28 14:59:14,652 log 1 140250374282040 Not Found: /tournament/get_current_id/
WARNING 2025-03-28 15:06:43,773 log 1 140250374282040 Not Found: /tournament/get_current_id/
WARNING 2025-03-28 15:10:35,419 log 1 140609217755960 Not Found: /tournament/get_current_id/
WARNING 2025-03-28 15:10:44,958 log 1 140609217755960 Not Found: /tournament/get_current_id/
WARNING 2025-03-28 15:16:13,294 log 1 140193395804984 Not Found: /tournament/get_current_id/
