WARNING 2025-03-28 13:30:26,541 log 1 139720866667320 Unauthorized: /auth/user/
WARNING 2025-03-28 13:32:41,208 log 1 139720866667320 Unauthorized: /auth/user/
WARNING 2025-03-28 13:32:44,232 log 1 139720866667320 Unauthorized: /auth/user/
WARNING 2025-03-28 13:32:51,871 log 1 139720866667320 Unauthorized: /auth/login/
WARNING 2025-03-28 13:41:49,943 log 1 140309905115960 Unauthorized: /auth/user/
WARNING 2025-03-28 13:41:51,127 log 1 140309905115960 Unauthorized: /auth/user/
WARNING 2025-03-28 13:43:27,648 log 1 140309905115960 Unauthorized: /auth/user/
WARNING 2025-03-28 13:43:37,184 log 1 140309905115960 Unauthorized: /auth/user/
WARNING 2025-03-28 12:27:43,437 log 1 140184401345336 Bad Request: /tournament/1/match/1/finish/
WARNING 2025-03-28 12:47:51,628 log 1 140402055445304 Bad Request: /tournament/37/match/46/finish/
WARNING 2025-03-28 13:15:59,299 log 1 140402055445304 Bad Request: /tournament/37/match/46/finish/
WARNING 2025-03-28 13:28:46,953 log 1 140115468991288 Bad Request: /tournament/38/match/55/finish/
WARNING 2025-03-28 13:43:58,230 log 1 140641825602360 Bad Request: /tournament/42/match/66/finish/
WARNING 2025-03-28 13:44:05,821 log 1 140641825602360 Bad Request: /tournament/42/match/66/finish/
WARNING 2025-03-28 13:50:12,400 log 1 139719942064952 Bad Request: /tournament/43/match/69/finish/
WARNING 2025-03-28 13:50:17,808 log 1 139719942064952 Bad Request: /tournament/43/match/69/finish/
WARNING 2025-03-28 13:50:26,551 log 1 139719942064952 Bad Request: /tournament/43/match/69/finish/
WARNING 2025-03-28 14:20:24,003 log 1 140637766646584 Not Found: /tournament/get_current_id/
WARNING 2025-03-28 14:22:19,059 log 1 140208776371000 Not Found: /tournament/get_current_id/
WARNING 2025-03-28 14:22:21,870 log 1 140208776371000 Not Found: /tournament/get_current_id/
WARNING 2025-03-28 14:22:23,616 log 1 140208776371000 Not Found: /tournament/get_current_id/
WARNING 2025-03-28 14:22:39,643 log 1 140208776371000 Not Found: /tournament/get_current_id/
WARNING 2025-03-28 14:24:09,790 log 1 140208776371000 Not Found: /tournament/get_current_id/
WARNING 2025-03-28 14:26:21,727 log 1 140432729361208 Not Found: /tournament/get_current_id/
WARNING 2025-03-28 14:34:02,430 log 1 140432729361208 Not Found: /tournament/get_current_id/
WARNING 2025-03-28 14:46:29,105 log 1 140622878882616 Not Found: /tournament/get_current_id/
WARNING 2025-03-28 14:46:51,150 log 1 140622878882616 Not Found: /tournament/get_current_id/
WARNING 2025-03-28 14:54:08,206 log 1 140636685114168 Not Found: /tournament/get_current_id/
WARNING 2025-03-28 14:57:54,144 log 1 140636685114168 Not Found: /tournament/get_current_id/
WARNING 2025-03-28 14:59:14,652 log 1 140250374282040 Not Found: /tournament/get_current_id/
WARNING 2025-03-28 15:06:43,773 log 1 140250374282040 Not Found: /tournament/get_current_id/
WARNING 2025-03-28 15:10:35,419 log 1 140609217755960 Not Found: /tournament/get_current_id/
WARNING 2025-03-28 15:10:44,958 log 1 140609217755960 Not Found: /tournament/get_current_id/
WARNING 2025-03-28 15:16:13,294 log 1 140193395804984 Not Found: /tournament/get_current_id/
WARNING 2025-03-28 16:59:28,940 log 1 140690324908856 Unauthorized: /auth/user/
WARNING 2025-03-28 16:59:30,025 log 1 140690324908856 Unauthorized: /auth/user/
WARNING 2025-03-28 16:59:44,759 log 1 140690324908856 Bad Request: /auth/signup/
WARNING 2025-03-28 16:59:52,277 log 1 140690324908856 Bad Request: /auth/signup/
WARNING 2025-03-28 16:59:57,982 log 1 140690324908856 Bad Request: /auth/signup/
WARNING 2025-03-28 17:00:05,850 log 1 140690324908856 Bad Request: /auth/signup/
WARNING 2025-03-28 17:00:23,664 log 1 140690324908856 Bad Request: /auth/signup/
WARNING 2025-03-28 17:12:27,610 log 1 140149891681080 Unauthorized: /auth/user/
WARNING 2025-03-28 17:12:41,756 log 1 140149891681080 Unauthorized: /auth/user/
WARNING 2025-03-28 17:12:43,102 log 1 140149891681080 Unauthorized: /auth/user/
WARNING 2025-03-29 09:38:20,297 log 1 140403071146808 Unauthorized: /auth/user/
WARNING 2025-03-29 09:38:36,421 log 1 140403071146808 Unauthorized: /auth/user/
WARNING 2025-03-29 09:38:37,285 log 1 140403071146808 Unauthorized: /auth/user/
WARNING 2025-03-29 09:38:46,155 log 1 140403071146808 Unauthorized: /api/game_settings/
WARNING 2025-03-29 09:38:46,155 log 1 140403066915640 Unauthorized: /api/game_settings/match_history/list/
WARNING 2025-03-29 09:38:52,375 log 1 140403066915640 Unauthorized: /api/game_settings/
WARNING 2025-03-29 09:39:10,594 log 1 140403071146808 Unauthorized: /api/game_settings/match_history/list/
WARNING 2025-03-29 09:39:10,594 log 1 140403066915640 Unauthorized: /api/game_settings/
WARNING 2025-03-29 09:39:14,087 log 1 140403066915640 Unauthorized: /api/game_settings/
WARNING 2025-03-29 09:39:14,087 log 1 140403071146808 Unauthorized: /api/game_settings/match_history/list/
WARNING 2025-03-29 09:39:15,548 log 1 140403066915640 Unauthorized: /api/game_settings/
WARNING 2025-03-29 09:39:15,549 log 1 140403066915640 Unauthorized: /api/game_settings/match_history/list/
WARNING 2025-03-29 09:39:16,059 log 1 140403071146808 Unauthorized: /api/game_settings/
WARNING 2025-03-29 09:39:16,060 log 1 140403066915640 Unauthorized: /api/game_settings/match_history/list/
WARNING 2025-03-29 09:39:16,837 log 1 140403071146808 Unauthorized: /api/game_settings/
WARNING 2025-03-29 09:39:16,837 log 1 140403066915640 Unauthorized: /api/game_settings/match_history/list/
WARNING 2025-03-29 09:39:17,240 log 1 140403066915640 Unauthorized: /api/game_settings/match_history/list/
WARNING 2025-03-29 09:39:17,241 log 1 140403071146808 Unauthorized: /api/game_settings/
WARNING 2025-03-29 09:39:17,913 log 1 140403066915640 Unauthorized: /api/game_settings/
WARNING 2025-03-29 09:39:17,914 log 1 140403071146808 Unauthorized: /api/game_settings/match_history/list/
WARNING 2025-03-29 09:39:21,783 log 1 140403066915640 Unauthorized: /api/game_settings/match_history/list/
WARNING 2025-03-29 09:39:21,783 log 1 140403071146808 Unauthorized: /api/game_settings/
WARNING 2025-03-29 09:39:25,754 log 1 140403066915640 Unauthorized: /api/game_settings/
WARNING 2025-03-29 09:39:25,754 log 1 140403071146808 Unauthorized: /api/game_settings/match_history/list/
WARNING 2025-03-29 09:39:28,457 log 1 140403066915640 Unauthorized: /api/game_settings/
WARNING 2025-03-29 09:39:33,858 log 1 140403071146808 Unauthorized: /api/game_settings/
WARNING 2025-03-29 09:39:33,858 log 1 140403066915640 Unauthorized: /api/game_settings/match_history/list/
WARNING 2025-03-29 09:39:37,498 log 1 140403066915640 Unauthorized: /api/game_settings/
WARNING 2025-03-29 09:39:40,799 log 1 140403071146808 Unauthorized: /api/game_settings/
WARNING 2025-03-29 09:39:40,799 log 1 140403066915640 Unauthorized: /api/game_settings/match_history/list/
WARNING 2025-03-29 09:39:41,623 log 1 140403071146808 Unauthorized: /auth/user/
WARNING 2025-03-29 09:39:45,321 log 1 140403066915640 Unauthorized: /auth/user/
WARNING 2025-03-29 09:39:47,677 log 1 140403066915640 Unauthorized: /auth/user/
WARNING 2025-03-29 09:39:49,716 log 1 140403071146808 Unauthorized: /auth/user/
WARNING 2025-03-29 09:40:01,920 log 1 140403066915640 Unauthorized: /api/game_settings/
WARNING 2025-03-29 09:40:01,920 log 1 140403066915640 Unauthorized: /api/game_settings/match_history/list/
WARNING 2025-03-29 09:41:19,342 log 1 140403066915640 Bad Request: /tournament/1/play_next/
WARNING 2025-03-29 09:41:20,934 log 1 140403071146808 Bad Request: /tournament/1/play_next/
WARNING 2025-03-29 09:41:24,259 log 1 140403066915640 Unauthorized: /api/game_settings/
WARNING 2025-03-29 09:41:33,758 log 1 140403071146808 Unauthorized: /api/game_settings/match_history/list/
WARNING 2025-03-29 09:41:33,758 log 1 140403066915640 Unauthorized: /api/game_settings/
WARNING 2025-03-29 09:41:34,441 log 1 140403066915640 Unauthorized: /api/game_settings/
WARNING 2025-03-29 09:41:34,441 log 1 140403071146808 Unauthorized: /api/game_settings/match_history/list/
WARNING 2025-03-29 09:41:34,930 log 1 140403066915640 Unauthorized: /api/game_settings/
WARNING 2025-03-29 09:41:34,930 log 1 140403071146808 Unauthorized: /api/game_settings/match_history/list/
WARNING 2025-03-29 09:44:14,651 log 1 140403066915640 Bad Request: /tournament/2/play_next/
WARNING 2025-03-29 09:44:16,985 log 1 140403071146808 Bad Request: /tournament/2/play_next/
WARNING 2025-03-29 10:44:46,981 log 1 140315340098360 Not Found: /favicon.ico
WARNING 2025-03-29 10:47:16,180 log 1 140315340098360 Not Found: /login/
WARNING 2025-03-29 10:52:11,515 log 1 140315340098360 Unauthorized: /auth/user/
WARNING 2025-03-29 11:01:29,321 log 1 140315340098360 Not Found: /auth/42/friends/remove/
WARNING 2025-03-29 11:08:04,140 log 1 140315340098360 Not Found: /auth/42/friends/request/
WARNING 2025-03-29 11:08:54,938 log 1 140315340098360 Not Found: /auth/42/friends/request/
WARNING 2025-03-29 11:10:01,576 log 1 140315340098360 Not Found: /auth/42/friends/request/
WARNING 2025-03-29 11:10:10,531 log 1 140315340098360 Not Found: /auth/42/friends/request/
WARNING 2025-03-29 17:17:54,711 log 1 140521220016952 Not Found: /auth/42/friends/search/
WARNING 2025-03-29 17:18:00,858 log 1 140521220016952 Not Found: /auth/42/friends/search/
WARNING 2025-03-29 17:18:07,078 log 1 140521220016952 Not Found: /auth/42/friends/search/
WARNING 2025-03-29 17:20:00,223 log 1 140521220016952 Not Found: /auth/42/friends/search/
WARNING 2025-03-29 17:20:02,918 log 1 140521220016952 Not Found: /auth/42/friends/search/
WARNING 2025-03-29 17:20:10,125 log 1 140521220016952 Not Found: /auth/42/friends/search/
WARNING 2025-03-29 17:34:42,336 log 1 140673393732408 Not Found: /auth/42/friends/search/
WARNING 2025-03-29 17:52:25,363 log 1 140323731565368 Not Found: /auth/42/friends/incoming/
WARNING 2025-03-29 17:52:55,500 log 1 140323731565368 Not Found: /auth/42/friends/incoming/
WARNING 2025-03-29 17:57:03,119 log 1 139757598354232 Not Found: /auth/42/friends/incoming/
WARNING 2025-03-29 18:02:49,918 log 1 139757598354232 Bad Request: /auth/42/friends/request/
WARNING 2025-03-29 18:02:49,937 log 1 139757598354232 Not Found: /auth/42/friends/remove/
WARNING 2025-03-29 18:02:49,959 log 1 139757598354232 Bad Request: /auth/42/friends/request/
WARNING 2025-03-29 18:02:49,996 log 1 139757598354232 Bad Request: /auth/42/friends/remove/
WARNING 2025-03-29 18:06:50,281 log 1 139993595038520 Unauthorized: /auth/login/
WARNING 2025-03-29 18:06:50,299 log 1 139993595038520 Unauthorized: /auth/login/
WARNING 2025-03-29 18:06:50,314 log 1 139993595038520 Unauthorized: /auth/42/users/search/
WARNING 2025-03-29 18:06:50,333 log 1 139993595038520 Unauthorized: /auth/42/friends/request/
WARNING 2025-03-29 18:06:50,347 log 1 139993595038520 Unauthorized: /auth/42/friends/incoming/
WARNING 2025-03-29 18:06:50,361 log 1 139993595038520 Unauthorized: /auth/42/friends/remove/
WARNING 2025-03-29 18:06:50,376 log 1 139993595038520 Unauthorized: /auth/42/friends/request/
WARNING 2025-03-29 18:06:50,391 log 1 139993595038520 Unauthorized: /auth/42/friends/incoming/
WARNING 2025-03-29 18:06:50,405 log 1 139993595038520 Unauthorized: /auth/42/friends/accept/
WARNING 2025-03-29 18:06:50,421 log 1 139993595038520 Unauthorized: /auth/42/friends/remove/
WARNING 2025-03-29 18:07:22,953 log 1 139993595038520 Unauthorized: /auth/login/
WARNING 2025-03-29 18:07:22,972 log 1 139993595038520 Unauthorized: /auth/login/
WARNING 2025-03-29 18:07:22,983 log 1 139993595038520 Unauthorized: /auth/42/users/search/
WARNING 2025-03-29 18:07:22,999 log 1 139993595038520 Unauthorized: /auth/42/friends/request/
WARNING 2025-03-29 18:07:23,012 log 1 139993595038520 Unauthorized: /auth/42/friends/incoming/
WARNING 2025-03-29 18:07:23,027 log 1 139993595038520 Unauthorized: /auth/42/friends/remove/
WARNING 2025-03-29 18:07:23,042 log 1 139993595038520 Unauthorized: /auth/42/friends/request/
WARNING 2025-03-29 18:07:23,056 log 1 139993595038520 Unauthorized: /auth/42/friends/incoming/
WARNING 2025-03-29 18:07:23,070 log 1 139993595038520 Unauthorized: /auth/42/friends/accept/
WARNING 2025-03-29 18:07:23,084 log 1 139993595038520 Unauthorized: /auth/42/friends/remove/
WARNING 2025-03-29 18:08:27,081 log 1 139993595038520 Not Found: /auth/42/friends/remove/
WARNING 2025-03-29 18:08:27,099 log 1 139993595038520 Bad Request: /auth/42/friends/request/
WARNING 2025-03-29 18:08:27,156 log 1 139993595038520 Bad Request: /auth/42/friends/remove/
WARNING 2025-03-29 18:56:23,972 log 1 140264611195704 Unauthorized: /auth/user/
WARNING 2025-03-29 18:56:57,645 log 1 140264611195704 Unauthorized: /auth/user/
WARNING 2025-03-29 18:56:58,563 log 1 140264611195704 Unauthorized: /auth/user/
WARNING 2025-03-29 18:57:09,930 log 1 140264606931768 Unauthorized: /api/game_settings/
WARNING 2025-03-29 18:57:09,931 log 1 140264611195704 Unauthorized: /api/game_settings/match_history/list/
WARNING 2025-03-29 18:57:11,167 log 1 140264606931768 Unauthorized: /api/game_settings/user_stats/
WARNING 2025-03-29 18:57:12,384 log 1 140264611195704 Unauthorized: /api/game_settings/
WARNING 2025-03-29 18:57:12,385 log 1 140264606931768 Unauthorized: /api/game_settings/match_history/list/
WARNING 2025-03-29 18:57:18,103 log 1 140264611195704 Unauthorized: /api/game_settings/
WARNING 2025-03-29 18:57:18,103 log 1 140264606931768 Unauthorized: /api/game_settings/match_history/list/
WARNING 2025-03-29 18:57:30,994 log 1 140264606931768 Unauthorized: /api/game_settings/match_history/list/
WARNING 2025-03-29 18:57:30,994 log 1 140264611195704 Unauthorized: /api/game_settings/
WARNING 2025-03-29 19:22:17,492 log 1 140376261880632 Unauthorized: /auth/users/search/
WARNING 2025-03-29 19:22:32,972 log 1 140376261880632 Unauthorized: /auth/42/users/search/
WARNING 2025-03-29 19:23:13,870 log 1 140376261880632 Unauthorized: /auth/42/users/search/
WARNING 2025-03-29 19:23:27,469 log 1 140376261880632 Bad Request: /auth/users/search/
WARNING 2025-03-29 19:43:41,272 log 1 140062268193592 Unauthorized: /auth/42/friends/request/
WARNING 2025-03-29 20:11:56,648 log 1 139922368092984 Bad Request: /auth/users/search/
WARNING 2025-03-29 20:47:09,843 log 1 140124891208504 Not Found: /auth/friends/
WARNING 2025-03-29 20:47:09,845 log 1 140124891208504 Not Found: /auth/users/search/
WARNING 2025-03-29 20:49:53,360 log 1 140124891208504 Not Found: /auth/friends/
WARNING 2025-03-29 20:49:53,363 log 1 140124891208504 Not Found: /auth/users/search/
WARNING 2025-03-29 20:51:09,239 log 1 140124891208504 Not Found: /auth/friends/
WARNING 2025-03-29 20:51:09,241 log 1 140124891208504 Not Found: /auth/users/search/
WARNING 2025-03-29 20:51:16,000 log 1 140124891208504 Not Found: /auth/friends/
WARNING 2025-03-29 20:51:16,006 log 1 140124891208504 Not Found: /auth/users/search/
WARNING 2025-03-29 20:51:16,680 log 1 140124891208504 Not Found: /auth/friends/
WARNING 2025-03-29 20:51:16,687 log 1 140124891208504 Not Found: /auth/users/search/
WARNING 2025-03-29 20:53:19,447 log 1 140337358408504 Not Found: /auth/42/friends/
WARNING 2025-03-29 20:53:19,451 log 1 140337358408504 Not Found: /auth/42/users/search/
WARNING 2025-03-29 20:56:07,306 log 1 140337358408504 Not Found: /auth/42/friends/
WARNING 2025-03-29 20:56:07,308 log 1 140337358408504 Not Found: /auth/42/users/search/
WARNING 2025-03-29 20:56:12,147 log 1 140337358408504 Not Found: /auth/42/friends/
WARNING 2025-03-29 20:56:12,156 log 1 140337358408504 Not Found: /auth/42/users/search/
WARNING 2025-03-29 20:56:12,985 log 1 140337358408504 Not Found: /auth/42/friends/
WARNING 2025-03-29 20:56:12,994 log 1 140337358408504 Not Found: /auth/42/users/search/
WARNING 2025-03-29 20:56:19,019 log 1 140337358408504 Not Found: /auth/42/friends/
WARNING 2025-03-29 20:56:19,020 log 1 140337358408504 Not Found: /auth/42/users/search/
WARNING 2025-03-29 20:58:21,836 log 1 139706960309048 Not Found: /auth/users/search/
WARNING 2025-03-29 20:58:21,838 log 1 139706960309048 Not Found: /auth/friends/
WARNING 2025-03-29 20:58:37,235 log 1 139706960309048 Not Found: /auth/users/search/
WARNING 2025-03-29 20:59:18,923 log 1 139706960309048 Not Found: /auth/users/search/
WARNING 2025-03-29 21:03:41,359 log 1 140287843240760 Not Found: /auth/friends/
WARNING 2025-03-29 21:03:41,359 log 1 140287844301624 Not Found: /auth/users/search/
WARNING 2025-03-29 21:03:46,186 log 1 140287843240760 Not Found: /auth/friends/
WARNING 2025-03-29 21:03:46,192 log 1 140287844301624 Not Found: /auth/users/search/
WARNING 2025-03-29 21:03:51,493 log 1 140287844301624 Not Found: /auth/friends/
WARNING 2025-03-29 21:03:51,497 log 1 140287843240760 Not Found: /auth/users/search/
WARNING 2025-03-29 21:03:57,092 log 1 140287843240760 Not Found: /auth/friends/
WARNING 2025-03-29 21:03:57,105 log 1 140287844301624 Not Found: /auth/users/search/
WARNING 2025-03-29 21:04:06,936 log 1 140287844301624 Not Found: /auth/friends/
WARNING 2025-03-29 21:04:06,939 log 1 140287843240760 Not Found: /auth/users/search/
WARNING 2025-03-29 21:04:21,569 log 1 140287843240760 Not Found: /auth/friends/
WARNING 2025-03-29 21:04:21,570 log 1 140287844301624 Not Found: /auth/users/search/
WARNING 2025-03-29 21:08:11,088 log 1 140216719407928 Not Found: /auth/friends/
WARNING 2025-03-29 21:08:11,088 log 1 140216718347064 Not Found: /auth/users/search/
WARNING 2025-03-29 21:13:16,518 log 1 140216718347064 Not Found: /auth/friends/
WARNING 2025-03-29 21:13:16,527 log 1 140216719407928 Not Found: /auth/users/search/
WARNING 2025-03-29 21:13:24,517 log 1 140216719407928 Not Found: /auth/friends/
WARNING 2025-03-29 21:13:24,525 log 1 140216718347064 Not Found: /auth/users/search/
WARNING 2025-03-29 21:17:23,553 log 1 140216718347064 Not Found: /auth/friends/
WARNING 2025-03-29 21:17:23,558 log 1 140216719407928 Not Found: /auth/users/search/
WARNING 2025-03-29 21:17:34,600 log 1 140216719407928 Not Found: /auth/friends/
WARNING 2025-03-29 21:17:34,604 log 1 140216718347064 Not Found: /auth/users/search/
WARNING 2025-03-29 21:19:46,565 log 1 140216719407928 Not Found: /auth/users/search/
WARNING 2025-03-29 21:26:03,455 log 1 140308768099128 Not Found: /auth/friends/
WARNING 2025-03-29 21:26:03,464 log 1 140308768099128 Not Found: /auth/users/search/
WARNING 2025-03-29 21:29:56,667 log 1 140308765989688 Not Found: /auth/users/search/
WARNING 2025-03-29 21:29:56,667 log 1 140308768099128 Not Found: /auth/friends/
WARNING 2025-03-29 21:30:06,509 log 1 140308768099128 Not Found: /auth/friends/
WARNING 2025-03-29 21:30:06,515 log 1 140308765989688 Not Found: /auth/users/search/
WARNING 2025-03-29 21:30:09,849 log 1 140308765989688 Not Found: /auth/friends/
WARNING 2025-03-29 21:30:09,854 log 1 140308768099128 Not Found: /auth/users/search/
ERROR 2025-03-29 21:34:59,347 log 1 140089042885432 Internal Server Error: /auth/users/search/
Traceback (most recent call last):
  File "/usr/local/lib/python3.10/site-packages/asgiref/sync.py", line 518, in thread_handler
    raise exc_info[1]
  File "/usr/local/lib/python3.10/site-packages/django/core/handlers/exception.py", line 42, in inner
    response = await get_response(request)
  File "/usr/local/lib/python3.10/site-packages/django/core/handlers/base.py", line 253, in _get_response_async
    response = await wrapped_callback(
  File "/usr/local/lib/python3.10/site-packages/asgiref/sync.py", line 468, in __call__
    ret = await asyncio.shield(exec_coro)
  File "/usr/local/lib/python3.10/site-packages/asgiref/current_thread_executor.py", line 40, in run
    result = self.fn(*self.args, **self.kwargs)
  File "/usr/local/lib/python3.10/site-packages/asgiref/sync.py", line 522, in thread_handler
    return func(*args, **kwargs)
  File "/usr/local/lib/python3.10/site-packages/django/views/decorators/csrf.py", line 56, in wrapper_view
    return view_func(*args, **kwargs)
  File "/app/./oauth_app/views.py", line 1271, in search_users_view
    incoming = set(req.from_user.user_id for req in current_user.incoming_requests.all())
AttributeError: 'User42' object has no attribute 'incoming_requests'
ERROR 2025-03-29 21:35:10,604 log 1 140089042885432 Internal Server Error: /auth/users/search/
Traceback (most recent call last):
  File "/usr/local/lib/python3.10/site-packages/asgiref/sync.py", line 518, in thread_handler
    raise exc_info[1]
  File "/usr/local/lib/python3.10/site-packages/django/core/handlers/exception.py", line 42, in inner
    response = await get_response(request)
  File "/usr/local/lib/python3.10/site-packages/django/core/handlers/base.py", line 253, in _get_response_async
    response = await wrapped_callback(
  File "/usr/local/lib/python3.10/site-packages/asgiref/sync.py", line 468, in __call__
    ret = await asyncio.shield(exec_coro)
  File "/usr/local/lib/python3.10/site-packages/asgiref/current_thread_executor.py", line 40, in run
    result = self.fn(*self.args, **self.kwargs)
  File "/usr/local/lib/python3.10/site-packages/asgiref/sync.py", line 522, in thread_handler
    return func(*args, **kwargs)
  File "/usr/local/lib/python3.10/site-packages/django/views/decorators/csrf.py", line 56, in wrapper_view
    return view_func(*args, **kwargs)
  File "/app/./oauth_app/views.py", line 1271, in search_users_view
    incoming = set(req.from_user.user_id for req in current_user.incoming_requests.all())
AttributeError: 'User42' object has no attribute 'incoming_requests'
ERROR 2025-03-29 21:35:32,358 log 1 140089042885432 Internal Server Error: /auth/users/search/
Traceback (most recent call last):
  File "/usr/local/lib/python3.10/site-packages/asgiref/sync.py", line 518, in thread_handler
    raise exc_info[1]
  File "/usr/local/lib/python3.10/site-packages/django/core/handlers/exception.py", line 42, in inner
    response = await get_response(request)
  File "/usr/local/lib/python3.10/site-packages/django/core/handlers/base.py", line 253, in _get_response_async
    response = await wrapped_callback(
  File "/usr/local/lib/python3.10/site-packages/asgiref/sync.py", line 468, in __call__
    ret = await asyncio.shield(exec_coro)
  File "/usr/local/lib/python3.10/site-packages/asgiref/current_thread_executor.py", line 40, in run
    result = self.fn(*self.args, **self.kwargs)
  File "/usr/local/lib/python3.10/site-packages/asgiref/sync.py", line 522, in thread_handler
    return func(*args, **kwargs)
  File "/usr/local/lib/python3.10/site-packages/django/views/decorators/csrf.py", line 56, in wrapper_view
    return view_func(*args, **kwargs)
  File "/app/./oauth_app/views.py", line 1271, in search_users_view
    incoming = set(req.from_user.user_id for req in current_user.incoming_requests.all())
AttributeError: 'User42' object has no attribute 'incoming_requests'
ERROR 2025-03-29 21:36:59,111 log 1 140089042885432 Internal Server Error: /auth/users/search/
Traceback (most recent call last):
  File "/usr/local/lib/python3.10/site-packages/asgiref/sync.py", line 518, in thread_handler
    raise exc_info[1]
  File "/usr/local/lib/python3.10/site-packages/django/core/handlers/exception.py", line 42, in inner
    response = await get_response(request)
  File "/usr/local/lib/python3.10/site-packages/django/core/handlers/base.py", line 253, in _get_response_async
    response = await wrapped_callback(
  File "/usr/local/lib/python3.10/site-packages/asgiref/sync.py", line 468, in __call__
    ret = await asyncio.shield(exec_coro)
  File "/usr/local/lib/python3.10/site-packages/asgiref/current_thread_executor.py", line 40, in run
    result = self.fn(*self.args, **self.kwargs)
  File "/usr/local/lib/python3.10/site-packages/asgiref/sync.py", line 522, in thread_handler
    return func(*args, **kwargs)
  File "/usr/local/lib/python3.10/site-packages/django/views/decorators/csrf.py", line 56, in wrapper_view
    return view_func(*args, **kwargs)
  File "/app/./oauth_app/views.py", line 1271, in search_users_view
    incoming = set(req.from_user.user_id for req in current_user.incoming_requests.all())
AttributeError: 'User42' object has no attribute 'incoming_requests'
ERROR 2025-03-29 21:40:07,134 log 1 140089042885432 Internal Server Error: /auth/users/search/
Traceback (most recent call last):
  File "/usr/local/lib/python3.10/site-packages/asgiref/sync.py", line 518, in thread_handler
    raise exc_info[1]
  File "/usr/local/lib/python3.10/site-packages/django/core/handlers/exception.py", line 42, in inner
    response = await get_response(request)
  File "/usr/local/lib/python3.10/site-packages/django/core/handlers/base.py", line 253, in _get_response_async
    response = await wrapped_callback(
  File "/usr/local/lib/python3.10/site-packages/asgiref/sync.py", line 468, in __call__
    ret = await asyncio.shield(exec_coro)
  File "/usr/local/lib/python3.10/site-packages/asgiref/current_thread_executor.py", line 40, in run
    result = self.fn(*self.args, **self.kwargs)
  File "/usr/local/lib/python3.10/site-packages/asgiref/sync.py", line 522, in thread_handler
    return func(*args, **kwargs)
  File "/usr/local/lib/python3.10/site-packages/django/views/decorators/csrf.py", line 56, in wrapper_view
    return view_func(*args, **kwargs)
  File "/app/./oauth_app/views.py", line 1271, in search_users_view
    incoming = set(req.from_user.user_id for req in current_user.incoming_requests.all())
AttributeError: 'User42' object has no attribute 'incoming_requests'
ERROR 2025-03-29 21:40:26,666 log 1 140089042885432 Internal Server Error: /auth/users/search/
Traceback (most recent call last):
  File "/usr/local/lib/python3.10/site-packages/asgiref/sync.py", line 518, in thread_handler
    raise exc_info[1]
  File "/usr/local/lib/python3.10/site-packages/django/core/handlers/exception.py", line 42, in inner
    response = await get_response(request)
  File "/usr/local/lib/python3.10/site-packages/django/core/handlers/base.py", line 253, in _get_response_async
    response = await wrapped_callback(
  File "/usr/local/lib/python3.10/site-packages/asgiref/sync.py", line 468, in __call__
    ret = await asyncio.shield(exec_coro)
  File "/usr/local/lib/python3.10/site-packages/asgiref/current_thread_executor.py", line 40, in run
    result = self.fn(*self.args, **self.kwargs)
  File "/usr/local/lib/python3.10/site-packages/asgiref/sync.py", line 522, in thread_handler
    return func(*args, **kwargs)
  File "/usr/local/lib/python3.10/site-packages/django/views/decorators/csrf.py", line 56, in wrapper_view
    return view_func(*args, **kwargs)
  File "/app/./oauth_app/views.py", line 1271, in search_users_view
    incoming = set(req.from_user.user_id for req in current_user.incoming_requests.all())
AttributeError: 'User42' object has no attribute 'incoming_requests'
ERROR 2025-03-29 21:43:03,137 log 1 140089042885432 Internal Server Error: /auth/users/search/
Traceback (most recent call last):
  File "/usr/local/lib/python3.10/site-packages/asgiref/sync.py", line 518, in thread_handler
    raise exc_info[1]
  File "/usr/local/lib/python3.10/site-packages/django/core/handlers/exception.py", line 42, in inner
    response = await get_response(request)
  File "/usr/local/lib/python3.10/site-packages/django/core/handlers/base.py", line 253, in _get_response_async
    response = await wrapped_callback(
  File "/usr/local/lib/python3.10/site-packages/asgiref/sync.py", line 468, in __call__
    ret = await asyncio.shield(exec_coro)
  File "/usr/local/lib/python3.10/site-packages/asgiref/current_thread_executor.py", line 40, in run
    result = self.fn(*self.args, **self.kwargs)
  File "/usr/local/lib/python3.10/site-packages/asgiref/sync.py", line 522, in thread_handler
    return func(*args, **kwargs)
  File "/usr/local/lib/python3.10/site-packages/django/views/decorators/csrf.py", line 56, in wrapper_view
    return view_func(*args, **kwargs)
  File "/app/./oauth_app/views.py", line 1271, in search_users_view
    incoming = set(req.from_user.user_id for req in current_user.incoming_requests.all())
AttributeError: 'User42' object has no attribute 'incoming_requests'
WARNING 2025-03-29 21:45:27,416 log 1 140423900265272 Not Found: /auth/friends/
ERROR 2025-03-29 21:45:27,453 log 1 140423902374712 Internal Server Error: /auth/42/users/search/
Traceback (most recent call last):
  File "/usr/local/lib/python3.10/site-packages/asgiref/sync.py", line 518, in thread_handler
    raise exc_info[1]
  File "/usr/local/lib/python3.10/site-packages/django/core/handlers/exception.py", line 42, in inner
    response = await get_response(request)
  File "/usr/local/lib/python3.10/site-packages/django/core/handlers/base.py", line 253, in _get_response_async
    response = await wrapped_callback(
  File "/usr/local/lib/python3.10/site-packages/asgiref/sync.py", line 468, in __call__
    ret = await asyncio.shield(exec_coro)
  File "/usr/local/lib/python3.10/site-packages/asgiref/current_thread_executor.py", line 40, in run
    result = self.fn(*self.args, **self.kwargs)
  File "/usr/local/lib/python3.10/site-packages/asgiref/sync.py", line 522, in thread_handler
    return func(*args, **kwargs)
  File "/usr/local/lib/python3.10/site-packages/django/views/decorators/csrf.py", line 56, in wrapper_view
    return view_func(*args, **kwargs)
  File "/app/./oauth_app/views.py", line 1271, in search_users_view
    incoming = set(req.from_user.user_id for req in current_user.incoming_requests.all())
AttributeError: 'User42' object has no attribute 'incoming_requests'
WARNING 2025-03-29 21:47:17,677 log 1 140423900265272 Not Found: /auth/friends/
ERROR 2025-03-29 21:47:17,700 log 1 140423900265272 Internal Server Error: /auth/42/users/search/
Traceback (most recent call last):
  File "/usr/local/lib/python3.10/site-packages/asgiref/sync.py", line 518, in thread_handler
    raise exc_info[1]
  File "/usr/local/lib/python3.10/site-packages/django/core/handlers/exception.py", line 42, in inner
    response = await get_response(request)
  File "/usr/local/lib/python3.10/site-packages/django/core/handlers/base.py", line 253, in _get_response_async
    response = await wrapped_callback(
  File "/usr/local/lib/python3.10/site-packages/asgiref/sync.py", line 468, in __call__
    ret = await asyncio.shield(exec_coro)
  File "/usr/local/lib/python3.10/site-packages/asgiref/current_thread_executor.py", line 40, in run
    result = self.fn(*self.args, **self.kwargs)
  File "/usr/local/lib/python3.10/site-packages/asgiref/sync.py", line 522, in thread_handler
    return func(*args, **kwargs)
  File "/usr/local/lib/python3.10/site-packages/django/views/decorators/csrf.py", line 56, in wrapper_view
    return view_func(*args, **kwargs)
  File "/app/./oauth_app/views.py", line 1271, in search_users_view
    incoming = set(req.from_user.user_id for req in current_user.incoming_requests.all())
AttributeError: 'User42' object has no attribute 'incoming_requests'
WARNING 2025-03-29 21:47:28,805 log 1 140423902374712 Not Found: /auth/friends/
ERROR 2025-03-29 21:47:28,832 log 1 140423900265272 Internal Server Error: /auth/42/users/search/
Traceback (most recent call last):
  File "/usr/local/lib/python3.10/site-packages/asgiref/sync.py", line 518, in thread_handler
    raise exc_info[1]
  File "/usr/local/lib/python3.10/site-packages/django/core/handlers/exception.py", line 42, in inner
    response = await get_response(request)
  File "/usr/local/lib/python3.10/site-packages/django/core/handlers/base.py", line 253, in _get_response_async
    response = await wrapped_callback(
  File "/usr/local/lib/python3.10/site-packages/asgiref/sync.py", line 468, in __call__
    ret = await asyncio.shield(exec_coro)
  File "/usr/local/lib/python3.10/site-packages/asgiref/current_thread_executor.py", line 40, in run
    result = self.fn(*self.args, **self.kwargs)
  File "/usr/local/lib/python3.10/site-packages/asgiref/sync.py", line 522, in thread_handler
    return func(*args, **kwargs)
  File "/usr/local/lib/python3.10/site-packages/django/views/decorators/csrf.py", line 56, in wrapper_view
    return view_func(*args, **kwargs)
  File "/app/./oauth_app/views.py", line 1271, in search_users_view
    incoming = set(req.from_user.user_id for req in current_user.incoming_requests.all())
AttributeError: 'User42' object has no attribute 'incoming_requests'
ERROR 2025-03-29 21:48:50,105 log 1 140196169153336 Internal Server Error: /auth/42/users/search/
Traceback (most recent call last):
  File "/usr/local/lib/python3.10/site-packages/asgiref/sync.py", line 518, in thread_handler
    raise exc_info[1]
  File "/usr/local/lib/python3.10/site-packages/django/core/handlers/exception.py", line 42, in inner
    response = await get_response(request)
  File "/usr/local/lib/python3.10/site-packages/django/core/handlers/base.py", line 253, in _get_response_async
    response = await wrapped_callback(
  File "/usr/local/lib/python3.10/site-packages/asgiref/sync.py", line 468, in __call__
    ret = await asyncio.shield(exec_coro)
  File "/usr/local/lib/python3.10/site-packages/asgiref/current_thread_executor.py", line 40, in run
    result = self.fn(*self.args, **self.kwargs)
  File "/usr/local/lib/python3.10/site-packages/asgiref/sync.py", line 522, in thread_handler
    return func(*args, **kwargs)
  File "/usr/local/lib/python3.10/site-packages/django/views/decorators/csrf.py", line 56, in wrapper_view
    return view_func(*args, **kwargs)
  File "/app/./oauth_app/views.py", line 1271, in search_users_view
    incoming = set(req.from_user.user_id for req in current_user.incoming_requests.all())
AttributeError: 'User42' object has no attribute 'incoming_requests'
ERROR 2025-03-29 21:49:21,746 log 1 140196169153336 Internal Server Error: /auth/42/users/search/
Traceback (most recent call last):
  File "/usr/local/lib/python3.10/site-packages/asgiref/sync.py", line 518, in thread_handler
    raise exc_info[1]
  File "/usr/local/lib/python3.10/site-packages/django/core/handlers/exception.py", line 42, in inner
    response = await get_response(request)
  File "/usr/local/lib/python3.10/site-packages/django/core/handlers/base.py", line 253, in _get_response_async
    response = await wrapped_callback(
  File "/usr/local/lib/python3.10/site-packages/asgiref/sync.py", line 468, in __call__
    ret = await asyncio.shield(exec_coro)
  File "/usr/local/lib/python3.10/site-packages/asgiref/current_thread_executor.py", line 40, in run
    result = self.fn(*self.args, **self.kwargs)
  File "/usr/local/lib/python3.10/site-packages/asgiref/sync.py", line 522, in thread_handler
    return func(*args, **kwargs)
  File "/usr/local/lib/python3.10/site-packages/django/views/decorators/csrf.py", line 56, in wrapper_view
    return view_func(*args, **kwargs)
  File "/app/./oauth_app/views.py", line 1271, in search_users_view
    incoming = set(req.from_user.user_id for req in current_user.incoming_requests.all())
AttributeError: 'User42' object has no attribute 'incoming_requests'
ERROR 2025-03-29 21:51:47,886 log 1 140472568625976 Internal Server Error: /auth/users/search/
Traceback (most recent call last):
  File "/usr/local/lib/python3.10/site-packages/asgiref/sync.py", line 518, in thread_handler
    raise exc_info[1]
  File "/usr/local/lib/python3.10/site-packages/django/core/handlers/exception.py", line 42, in inner
    response = await get_response(request)
  File "/usr/local/lib/python3.10/site-packages/django/core/handlers/base.py", line 253, in _get_response_async
    response = await wrapped_callback(
  File "/usr/local/lib/python3.10/site-packages/asgiref/sync.py", line 468, in __call__
    ret = await asyncio.shield(exec_coro)
  File "/usr/local/lib/python3.10/site-packages/asgiref/current_thread_executor.py", line 40, in run
    result = self.fn(*self.args, **self.kwargs)
  File "/usr/local/lib/python3.10/site-packages/asgiref/sync.py", line 522, in thread_handler
    return func(*args, **kwargs)
  File "/usr/local/lib/python3.10/site-packages/django/views/decorators/csrf.py", line 56, in wrapper_view
    return view_func(*args, **kwargs)
  File "/app/./oauth_app/views.py", line 1271, in search_users_view
    incoming = set(req.from_user.user_id for req in current_user.incoming_requests.all())
AttributeError: 'User42' object has no attribute 'incoming_requests'
ERROR 2025-03-29 21:54:17,687 log 1 140472568625976 Internal Server Error: /auth/users/search/
Traceback (most recent call last):
  File "/usr/local/lib/python3.10/site-packages/asgiref/sync.py", line 518, in thread_handler
    raise exc_info[1]
  File "/usr/local/lib/python3.10/site-packages/django/core/handlers/exception.py", line 42, in inner
    response = await get_response(request)
  File "/usr/local/lib/python3.10/site-packages/django/core/handlers/base.py", line 253, in _get_response_async
    response = await wrapped_callback(
  File "/usr/local/lib/python3.10/site-packages/asgiref/sync.py", line 468, in __call__
    ret = await asyncio.shield(exec_coro)
  File "/usr/local/lib/python3.10/site-packages/asgiref/current_thread_executor.py", line 40, in run
    result = self.fn(*self.args, **self.kwargs)
  File "/usr/local/lib/python3.10/site-packages/asgiref/sync.py", line 522, in thread_handler
    return func(*args, **kwargs)
  File "/usr/local/lib/python3.10/site-packages/django/views/decorators/csrf.py", line 56, in wrapper_view
    return view_func(*args, **kwargs)
  File "/app/./oauth_app/views.py", line 1271, in search_users_view
    incoming = set(req.from_user.user_id for req in current_user.incoming_requests.all())
AttributeError: 'User42' object has no attribute 'incoming_requests'
ERROR 2025-03-29 21:55:16,768 log 1 140472568625976 Internal Server Error: /auth/users/search/
Traceback (most recent call last):
  File "/usr/local/lib/python3.10/site-packages/asgiref/sync.py", line 518, in thread_handler
    raise exc_info[1]
  File "/usr/local/lib/python3.10/site-packages/django/core/handlers/exception.py", line 42, in inner
    response = await get_response(request)
  File "/usr/local/lib/python3.10/site-packages/django/core/handlers/base.py", line 253, in _get_response_async
    response = await wrapped_callback(
  File "/usr/local/lib/python3.10/site-packages/asgiref/sync.py", line 468, in __call__
    ret = await asyncio.shield(exec_coro)
  File "/usr/local/lib/python3.10/site-packages/asgiref/current_thread_executor.py", line 40, in run
    result = self.fn(*self.args, **self.kwargs)
  File "/usr/local/lib/python3.10/site-packages/asgiref/sync.py", line 522, in thread_handler
    return func(*args, **kwargs)
  File "/usr/local/lib/python3.10/site-packages/django/views/decorators/csrf.py", line 56, in wrapper_view
    return view_func(*args, **kwargs)
  File "/app/./oauth_app/views.py", line 1271, in search_users_view
    incoming = set(req.from_user.user_id for req in current_user.incoming_requests.all())
AttributeError: 'User42' object has no attribute 'incoming_requests'
ERROR 2025-03-29 21:55:22,119 log 1 140472568625976 Internal Server Error: /auth/users/search/
Traceback (most recent call last):
  File "/usr/local/lib/python3.10/site-packages/asgiref/sync.py", line 518, in thread_handler
    raise exc_info[1]
  File "/usr/local/lib/python3.10/site-packages/django/core/handlers/exception.py", line 42, in inner
    response = await get_response(request)
  File "/usr/local/lib/python3.10/site-packages/django/core/handlers/base.py", line 253, in _get_response_async
    response = await wrapped_callback(
  File "/usr/local/lib/python3.10/site-packages/asgiref/sync.py", line 468, in __call__
    ret = await asyncio.shield(exec_coro)
  File "/usr/local/lib/python3.10/site-packages/asgiref/current_thread_executor.py", line 40, in run
    result = self.fn(*self.args, **self.kwargs)
  File "/usr/local/lib/python3.10/site-packages/asgiref/sync.py", line 522, in thread_handler
    return func(*args, **kwargs)
  File "/usr/local/lib/python3.10/site-packages/django/views/decorators/csrf.py", line 56, in wrapper_view
    return view_func(*args, **kwargs)
  File "/app/./oauth_app/views.py", line 1271, in search_users_view
    incoming = set(req.from_user.user_id for req in current_user.incoming_requests.all())
AttributeError: 'User42' object has no attribute 'incoming_requests'
ERROR 2025-03-29 21:58:22,662 log 1 140248863562552 Internal Server Error: /auth/users/search/
Traceback (most recent call last):
  File "/usr/local/lib/python3.10/site-packages/asgiref/sync.py", line 518, in thread_handler
    raise exc_info[1]
  File "/usr/local/lib/python3.10/site-packages/django/core/handlers/exception.py", line 42, in inner
    response = await get_response(request)
  File "/usr/local/lib/python3.10/site-packages/django/core/handlers/base.py", line 253, in _get_response_async
    response = await wrapped_callback(
  File "/usr/local/lib/python3.10/site-packages/asgiref/sync.py", line 468, in __call__
    ret = await asyncio.shield(exec_coro)
  File "/usr/local/lib/python3.10/site-packages/asgiref/current_thread_executor.py", line 40, in run
    result = self.fn(*self.args, **self.kwargs)
  File "/usr/local/lib/python3.10/site-packages/asgiref/sync.py", line 522, in thread_handler
    return func(*args, **kwargs)
  File "/usr/local/lib/python3.10/site-packages/django/views/decorators/csrf.py", line 56, in wrapper_view
    return view_func(*args, **kwargs)
  File "/app/./oauth_app/views.py", line 1271, in search_users_view
    incoming = set(req.from_user.user_id for req in current_user.incoming_requests.all())
AttributeError: 'User42' object has no attribute 'incoming_requests'
ERROR 2025-03-29 22:04:45,434 log 1 140248863562552 Internal Server Error: /auth/users/search/
Traceback (most recent call last):
  File "/usr/local/lib/python3.10/site-packages/asgiref/sync.py", line 518, in thread_handler
    raise exc_info[1]
  File "/usr/local/lib/python3.10/site-packages/django/core/handlers/exception.py", line 42, in inner
    response = await get_response(request)
  File "/usr/local/lib/python3.10/site-packages/django/core/handlers/base.py", line 253, in _get_response_async
    response = await wrapped_callback(
  File "/usr/local/lib/python3.10/site-packages/asgiref/sync.py", line 468, in __call__
    ret = await asyncio.shield(exec_coro)
  File "/usr/local/lib/python3.10/site-packages/asgiref/current_thread_executor.py", line 40, in run
    result = self.fn(*self.args, **self.kwargs)
  File "/usr/local/lib/python3.10/site-packages/asgiref/sync.py", line 522, in thread_handler
    return func(*args, **kwargs)
  File "/usr/local/lib/python3.10/site-packages/django/views/decorators/csrf.py", line 56, in wrapper_view
    return view_func(*args, **kwargs)
  File "/app/./oauth_app/views.py", line 1271, in search_users_view
    incoming = set(req.from_user.user_id for req in current_user.incoming_requests.all())
AttributeError: 'User42' object has no attribute 'incoming_requests'
ERROR 2025-03-29 22:05:10,580 log 1 140248863562552 Internal Server Error: /auth/users/search/
Traceback (most recent call last):
  File "/usr/local/lib/python3.10/site-packages/asgiref/sync.py", line 518, in thread_handler
    raise exc_info[1]
  File "/usr/local/lib/python3.10/site-packages/django/core/handlers/exception.py", line 42, in inner
    response = await get_response(request)
  File "/usr/local/lib/python3.10/site-packages/django/core/handlers/base.py", line 253, in _get_response_async
    response = await wrapped_callback(
  File "/usr/local/lib/python3.10/site-packages/asgiref/sync.py", line 468, in __call__
    ret = await asyncio.shield(exec_coro)
  File "/usr/local/lib/python3.10/site-packages/asgiref/current_thread_executor.py", line 40, in run
    result = self.fn(*self.args, **self.kwargs)
  File "/usr/local/lib/python3.10/site-packages/asgiref/sync.py", line 522, in thread_handler
    return func(*args, **kwargs)
  File "/usr/local/lib/python3.10/site-packages/django/views/decorators/csrf.py", line 56, in wrapper_view
    return view_func(*args, **kwargs)
  File "/app/./oauth_app/views.py", line 1271, in search_users_view
    incoming = set(req.from_user.user_id for req in current_user.incoming_requests.all())
AttributeError: 'User42' object has no attribute 'incoming_requests'
ERROR 2025-03-29 22:08:26,192 log 1 140241293720376 Internal Server Error: /auth/users/search/
Traceback (most recent call last):
  File "/usr/local/lib/python3.10/site-packages/asgiref/sync.py", line 518, in thread_handler
    raise exc_info[1]
  File "/usr/local/lib/python3.10/site-packages/django/core/handlers/exception.py", line 42, in inner
    response = await get_response(request)
  File "/usr/local/lib/python3.10/site-packages/django/core/handlers/base.py", line 253, in _get_response_async
    response = await wrapped_callback(
  File "/usr/local/lib/python3.10/site-packages/asgiref/sync.py", line 468, in __call__
    ret = await asyncio.shield(exec_coro)
  File "/usr/local/lib/python3.10/site-packages/asgiref/current_thread_executor.py", line 40, in run
    result = self.fn(*self.args, **self.kwargs)
  File "/usr/local/lib/python3.10/site-packages/asgiref/sync.py", line 522, in thread_handler
    return func(*args, **kwargs)
  File "/usr/local/lib/python3.10/site-packages/django/views/decorators/csrf.py", line 56, in wrapper_view
    return view_func(*args, **kwargs)
  File "/app/./oauth_app/views.py", line 1271, in search_users_view
    incoming = set(req.from_user.user_id for req in current_user.incoming_requests.all())
AttributeError: 'User42' object has no attribute 'incoming_requests'
ERROR 2025-03-29 22:13:47,992 log 1 140441004141368 Internal Server Error: /auth/users/search/
Traceback (most recent call last):
  File "/usr/local/lib/python3.10/site-packages/asgiref/sync.py", line 518, in thread_handler
    raise exc_info[1]
  File "/usr/local/lib/python3.10/site-packages/django/core/handlers/exception.py", line 42, in inner
    response = await get_response(request)
  File "/usr/local/lib/python3.10/site-packages/django/core/handlers/base.py", line 253, in _get_response_async
    response = await wrapped_callback(
  File "/usr/local/lib/python3.10/site-packages/asgiref/sync.py", line 468, in __call__
    ret = await asyncio.shield(exec_coro)
  File "/usr/local/lib/python3.10/site-packages/asgiref/current_thread_executor.py", line 40, in run
    result = self.fn(*self.args, **self.kwargs)
  File "/usr/local/lib/python3.10/site-packages/asgiref/sync.py", line 522, in thread_handler
    return func(*args, **kwargs)
  File "/usr/local/lib/python3.10/site-packages/django/views/decorators/csrf.py", line 56, in wrapper_view
    return view_func(*args, **kwargs)
  File "/app/./oauth_app/views.py", line 1271, in search_users_view
    incoming = set(req.from_user.user_id for req in current_user.incoming_requests.all())
AttributeError: 'User42' object has no attribute 'incoming_requests'
ERROR 2025-03-29 22:23:27,212 log 1 140172697807672 Internal Server Error: /auth/user/search/
Traceback (most recent call last):
  File "/usr/local/lib/python3.10/site-packages/asgiref/sync.py", line 518, in thread_handler
    raise exc_info[1]
  File "/usr/local/lib/python3.10/site-packages/django/core/handlers/exception.py", line 42, in inner
    response = await get_response(request)
  File "/usr/local/lib/python3.10/site-packages/django/core/handlers/base.py", line 253, in _get_response_async
    response = await wrapped_callback(
  File "/usr/local/lib/python3.10/site-packages/asgiref/sync.py", line 468, in __call__
    ret = await asyncio.shield(exec_coro)
  File "/usr/local/lib/python3.10/site-packages/asgiref/current_thread_executor.py", line 40, in run
    result = self.fn(*self.args, **self.kwargs)
  File "/usr/local/lib/python3.10/site-packages/asgiref/sync.py", line 522, in thread_handler
    return func(*args, **kwargs)
  File "/usr/local/lib/python3.10/site-packages/django/views/decorators/csrf.py", line 56, in wrapper_view
    return view_func(*args, **kwargs)
  File "/app/./oauth_app/views.py", line 1271, in search_users_view
    incoming = set(req.from_user.user_id for req in current_user.incoming_requests.all())
AttributeError: 'User42' object has no attribute 'incoming_requests'
WARNING 2025-03-29 22:40:53,441 log 1 140225046014776 Bad Request: /auth/42/friends/accept/
WARNING 2025-03-29 22:42:03,311 log 1 140225046014776 Bad Request: /auth/42/friends/accept/
WARNING 2025-03-29 22:44:40,321 log 1 140225046014776 Unauthorized: /auth/42/friends/request/
WARNING 2025-03-29 22:45:45,973 log 1 140225046014776 Bad Request: /auth/friends/accept/
WARNING 2025-03-29 22:46:04,731 log 1 140225046014776 Bad Request: /auth/friends/accept/
WARNING 2025-03-29 22:46:09,876 log 1 140225046014776 Bad Request: /auth/friends/accept/
WARNING 2025-03-29 22:46:52,338 log 1 140225046014776 Bad Request: /auth/friends/accept/
WARNING 2025-03-29 22:46:58,136 log 1 140225046014776 Bad Request: /auth/friends/accept/
WARNING 2025-03-29 22:49:19,843 log 1 140225046014776 Bad Request: /auth/friends/accept/
WARNING 2025-03-31 02:52:05,001 log 1 280817709468136 Unauthorized: /auth/user/
WARNING 2025-03-31 02:52:07,632 log 1 280817709468136 Unauthorized: /auth/user/
WARNING 2025-03-31 02:52:21,700 log 1 280817709468136 Unauthorized: /auth/user/
WARNING 2025-03-31 02:52:24,136 log 1 280817709468136 Unauthorized: /auth/user/
WARNING 2025-03-31 02:52:35,159 log 1 280817709468136 Unauthorized: /api/game_settings/match_history/list/
WARNING 2025-03-31 02:52:35,159 log 1 280817706297832 Unauthorized: /api/game_settings/
WARNING 2025-03-31 02:52:45,483 log 1 280817709468136 Unauthorized: /auth/user/
WARNING 2025-03-31 02:52:46,220 log 1 280817706297832 Unauthorized: /auth/user/
WARNING 2025-03-31 02:52:58,773 log 1 280817709468136 Unauthorized: /api/game_settings/match_history/list/
WARNING 2025-03-31 02:52:58,773 log 1 280817706297832 Unauthorized: /api/game_settings/
WARNING 2025-03-31 03:26:55,183 log 1 260713537620456 Unauthorized: /auth/user/
WARNING 2025-03-31 03:26:55,196 log 1 260713537620456 Unauthorized: /auth/user/
WARNING 2025-03-31 04:13:39,622 log 1 252105924110824 Unauthorized: /auth/user/
