WARNING 2025-03-28 13:30:26,541 log 1 139720866667320 Unauthorized: /auth/user/
WARNING 2025-03-28 13:32:41,208 log 1 139720866667320 Unauthorized: /auth/user/
WARNING 2025-03-28 13:32:44,232 log 1 139720866667320 Unauthorized: /auth/user/
WARNING 2025-03-28 13:32:51,871 log 1 139720866667320 Unauthorized: /auth/login/
WARNING 2025-03-28 13:41:49,943 log 1 140309905115960 Unauthorized: /auth/user/
WARNING 2025-03-28 13:41:51,127 log 1 140309905115960 Unauthorized: /auth/user/
WARNING 2025-03-28 13:43:27,648 log 1 140309905115960 Unauthorized: /auth/user/
WARNING 2025-03-28 13:43:37,184 log 1 140309905115960 Unauthorized: /auth/user/
WARNING 2025-03-28 12:27:43,437 log 1 140184401345336 Bad Request: /tournament/1/match/1/finish/
WARNING 2025-03-28 12:47:51,628 log 1 140402055445304 Bad Request: /tournament/37/match/46/finish/
WARNING 2025-03-28 13:15:59,299 log 1 140402055445304 Bad Request: /tournament/37/match/46/finish/
WARNING 2025-03-28 13:28:46,953 log 1 140115468991288 Bad Request: /tournament/38/match/55/finish/
WARNING 2025-03-28 13:43:58,230 log 1 140641825602360 Bad Request: /tournament/42/match/66/finish/
WARNING 2025-03-28 13:44:05,821 log 1 140641825602360 Bad Request: /tournament/42/match/66/finish/
WARNING 2025-03-28 13:50:12,400 log 1 139719942064952 Bad Request: /tournament/43/match/69/finish/
WARNING 2025-03-28 13:50:17,808 log 1 139719942064952 Bad Request: /tournament/43/match/69/finish/
WARNING 2025-03-28 13:50:26,551 log 1 139719942064952 Bad Request: /tournament/43/match/69/finish/
WARNING 2025-03-28 14:20:24,003 log 1 140637766646584 Not Found: /tournament/get_current_id/
WARNING 2025-03-28 14:22:19,059 log 1 140208776371000 Not Found: /tournament/get_current_id/
WARNING 2025-03-28 14:22:21,870 log 1 140208776371000 Not Found: /tournament/get_current_id/
WARNING 2025-03-28 14:22:23,616 log 1 140208776371000 Not Found: /tournament/get_current_id/
WARNING 2025-03-28 14:22:39,643 log 1 140208776371000 Not Found: /tournament/get_current_id/
WARNING 2025-03-28 14:24:09,790 log 1 140208776371000 Not Found: /tournament/get_current_id/
WARNING 2025-03-28 14:26:21,727 log 1 140432729361208 Not Found: /tournament/get_current_id/
WARNING 2025-03-28 14:34:02,430 log 1 140432729361208 Not Found: /tournament/get_current_id/
WARNING 2025-03-28 14:46:29,105 log 1 140622878882616 Not Found: /tournament/get_current_id/
WARNING 2025-03-28 14:46:51,150 log 1 140622878882616 Not Found: /tournament/get_current_id/
WARNING 2025-03-28 14:54:08,206 log 1 140636685114168 Not Found: /tournament/get_current_id/
WARNING 2025-03-28 14:57:54,144 log 1 140636685114168 Not Found: /tournament/get_current_id/
WARNING 2025-03-28 14:59:14,652 log 1 140250374282040 Not Found: /tournament/get_current_id/
WARNING 2025-03-28 15:06:43,773 log 1 140250374282040 Not Found: /tournament/get_current_id/
WARNING 2025-03-28 15:10:35,419 log 1 140609217755960 Not Found: /tournament/get_current_id/
WARNING 2025-03-28 15:10:44,958 log 1 140609217755960 Not Found: /tournament/get_current_id/
WARNING 2025-03-28 15:16:13,294 log 1 140193395804984 Not Found: /tournament/get_current_id/
WARNING 2025-03-28 16:59:28,940 log 1 140690324908856 Unauthorized: /auth/user/
WARNING 2025-03-28 16:59:30,025 log 1 140690324908856 Unauthorized: /auth/user/
WARNING 2025-03-28 16:59:44,759 log 1 140690324908856 Bad Request: /auth/signup/
WARNING 2025-03-28 16:59:52,277 log 1 140690324908856 Bad Request: /auth/signup/
WARNING 2025-03-28 16:59:57,982 log 1 140690324908856 Bad Request: /auth/signup/
WARNING 2025-03-28 17:00:05,850 log 1 140690324908856 Bad Request: /auth/signup/
WARNING 2025-03-28 17:00:23,664 log 1 140690324908856 Bad Request: /auth/signup/
WARNING 2025-03-28 17:12:27,610 log 1 140149891681080 Unauthorized: /auth/user/
WARNING 2025-03-28 17:12:41,756 log 1 140149891681080 Unauthorized: /auth/user/
WARNING 2025-03-28 17:12:43,102 log 1 140149891681080 Unauthorized: /auth/user/
WARNING 2025-03-29 09:38:20,297 log 1 140403071146808 Unauthorized: /auth/user/
WARNING 2025-03-29 09:38:36,421 log 1 140403071146808 Unauthorized: /auth/user/
WARNING 2025-03-29 09:38:37,285 log 1 140403071146808 Unauthorized: /auth/user/
WARNING 2025-03-29 09:38:46,155 log 1 140403071146808 Unauthorized: /api/game_settings/
WARNING 2025-03-29 09:38:46,155 log 1 140403066915640 Unauthorized: /api/game_settings/match_history/list/
WARNING 2025-03-29 09:38:52,375 log 1 140403066915640 Unauthorized: /api/game_settings/
WARNING 2025-03-29 09:39:10,594 log 1 140403071146808 Unauthorized: /api/game_settings/match_history/list/
WARNING 2025-03-29 09:39:10,594 log 1 140403066915640 Unauthorized: /api/game_settings/
WARNING 2025-03-29 09:39:14,087 log 1 140403066915640 Unauthorized: /api/game_settings/
WARNING 2025-03-29 09:39:14,087 log 1 140403071146808 Unauthorized: /api/game_settings/match_history/list/
WARNING 2025-03-29 09:39:15,548 log 1 140403066915640 Unauthorized: /api/game_settings/
WARNING 2025-03-29 09:39:15,549 log 1 140403066915640 Unauthorized: /api/game_settings/match_history/list/
WARNING 2025-03-29 09:39:16,059 log 1 140403071146808 Unauthorized: /api/game_settings/
WARNING 2025-03-29 09:39:16,060 log 1 140403066915640 Unauthorized: /api/game_settings/match_history/list/
WARNING 2025-03-29 09:39:16,837 log 1 140403071146808 Unauthorized: /api/game_settings/
WARNING 2025-03-29 09:39:16,837 log 1 140403066915640 Unauthorized: /api/game_settings/match_history/list/
WARNING 2025-03-29 09:39:17,240 log 1 140403066915640 Unauthorized: /api/game_settings/match_history/list/
WARNING 2025-03-29 09:39:17,241 log 1 140403071146808 Unauthorized: /api/game_settings/
WARNING 2025-03-29 09:39:17,913 log 1 140403066915640 Unauthorized: /api/game_settings/
WARNING 2025-03-29 09:39:17,914 log 1 140403071146808 Unauthorized: /api/game_settings/match_history/list/
WARNING 2025-03-29 09:39:21,783 log 1 140403066915640 Unauthorized: /api/game_settings/match_history/list/
WARNING 2025-03-29 09:39:21,783 log 1 140403071146808 Unauthorized: /api/game_settings/
WARNING 2025-03-29 09:39:25,754 log 1 140403066915640 Unauthorized: /api/game_settings/
WARNING 2025-03-29 09:39:25,754 log 1 140403071146808 Unauthorized: /api/game_settings/match_history/list/
WARNING 2025-03-29 09:39:28,457 log 1 140403066915640 Unauthorized: /api/game_settings/
WARNING 2025-03-29 09:39:33,858 log 1 140403071146808 Unauthorized: /api/game_settings/
WARNING 2025-03-29 09:39:33,858 log 1 140403066915640 Unauthorized: /api/game_settings/match_history/list/
WARNING 2025-03-29 09:39:37,498 log 1 140403066915640 Unauthorized: /api/game_settings/
WARNING 2025-03-29 09:39:40,799 log 1 140403071146808 Unauthorized: /api/game_settings/
WARNING 2025-03-29 09:39:40,799 log 1 140403066915640 Unauthorized: /api/game_settings/match_history/list/
WARNING 2025-03-29 09:39:41,623 log 1 140403071146808 Unauthorized: /auth/user/
WARNING 2025-03-29 09:39:45,321 log 1 140403066915640 Unauthorized: /auth/user/
WARNING 2025-03-29 09:39:47,677 log 1 140403066915640 Unauthorized: /auth/user/
WARNING 2025-03-29 09:39:49,716 log 1 140403071146808 Unauthorized: /auth/user/
WARNING 2025-03-29 09:40:01,920 log 1 140403066915640 Unauthorized: /api/game_settings/
WARNING 2025-03-29 09:40:01,920 log 1 140403066915640 Unauthorized: /api/game_settings/match_history/list/
WARNING 2025-03-29 09:41:19,342 log 1 140403066915640 Bad Request: /tournament/1/play_next/
WARNING 2025-03-29 09:41:20,934 log 1 140403071146808 Bad Request: /tournament/1/play_next/
WARNING 2025-03-29 09:41:24,259 log 1 140403066915640 Unauthorized: /api/game_settings/
WARNING 2025-03-29 09:41:33,758 log 1 140403071146808 Unauthorized: /api/game_settings/match_history/list/
WARNING 2025-03-29 09:41:33,758 log 1 140403066915640 Unauthorized: /api/game_settings/
WARNING 2025-03-29 09:41:34,441 log 1 140403066915640 Unauthorized: /api/game_settings/
WARNING 2025-03-29 09:41:34,441 log 1 140403071146808 Unauthorized: /api/game_settings/match_history/list/
WARNING 2025-03-29 09:41:34,930 log 1 140403066915640 Unauthorized: /api/game_settings/
WARNING 2025-03-29 09:41:34,930 log 1 140403071146808 Unauthorized: /api/game_settings/match_history/list/
WARNING 2025-03-29 09:44:14,651 log 1 140403066915640 Bad Request: /tournament/2/play_next/
WARNING 2025-03-29 09:44:16,985 log 1 140403071146808 Bad Request: /tournament/2/play_next/
WARNING 2025-03-29 10:44:46,981 log 1 140315340098360 Not Found: /favicon.ico
WARNING 2025-03-29 10:47:16,180 log 1 140315340098360 Not Found: /login/
WARNING 2025-03-29 10:52:11,515 log 1 140315340098360 Unauthorized: /auth/user/
WARNING 2025-03-29 11:01:29,321 log 1 140315340098360 Not Found: /auth/42/friends/remove/
WARNING 2025-03-29 11:08:04,140 log 1 140315340098360 Not Found: /auth/42/friends/request/
WARNING 2025-03-29 11:08:54,938 log 1 140315340098360 Not Found: /auth/42/friends/request/
WARNING 2025-03-29 11:10:01,576 log 1 140315340098360 Not Found: /auth/42/friends/request/
WARNING 2025-03-29 11:10:10,531 log 1 140315340098360 Not Found: /auth/42/friends/request/
WARNING 2025-03-29 15:40:15,108 log 1 140179468172088 Not Found: /favicon.ico
WARNING 2025-03-29 15:51:23,450 log 1 140601449651000 Not Found: /favicon.ico
WARNING 2025-03-29 16:03:36,648 log 1 139956592970552 Not Found: /favicon.ico
WARNING 2025-03-29 16:07:46,339 log 1 140606683446072 Bad Request: /tournament/1/play_next/
WARNING 2025-03-29 16:48:40,940 log 1 140427546753848 Unauthorized: /api/game_settings/
WARNING 2025-03-29 16:48:40,943 log 1 140427546753848 Unauthorized: /api/game_settings/match_history/list/
WARNING 2025-03-29 16:48:42,429 log 1 140427546753848 Unauthorized: /api/game_settings/user_stats/
WARNING 2025-03-29 16:48:47,235 log 1 140427546753848 Unauthorized: /api/game_settings/match_history/list/
WARNING 2025-03-29 16:48:47,237 log 1 140427546753848 Unauthorized: /api/game_settings/
WARNING 2025-03-29 16:48:49,420 log 1 140427546753848 Unauthorized: /api/game_settings/
WARNING 2025-03-29 16:49:09,800 log 1 140427546753848 Unauthorized: /api/game_settings/match_history/
WARNING 2025-03-29 16:49:11,672 log 1 140427546753848 Unauthorized: /api/game_settings/match_history/list/
WARNING 2025-03-29 16:49:11,672 log 1 140427546753848 Unauthorized: /api/game_settings/
WARNING 2025-03-29 16:49:15,395 log 1 140427546753848 Unauthorized: /api/game_settings/user_stats/
WARNING 2025-03-29 16:50:24,752 log 1 140300170517304 Unauthorized: /api/game_settings/
WARNING 2025-03-29 16:50:24,755 log 1 140300170517304 Unauthorized: /api/game_settings/match_history/list/
WARNING 2025-03-29 16:51:44,778 log 1 140300170517304 Bad Request: /tournament/create/
ERROR 2025-03-29 16:59:42,852 log 1 139900017568568 Internal Server Error: /tournament/10/match/19/finish/
Traceback (most recent call last):
  File "/usr/local/lib/python3.10/site-packages/asgiref/sync.py", line 518, in thread_handler
    raise exc_info[1]
  File "/usr/local/lib/python3.10/site-packages/django/core/handlers/exception.py", line 42, in inner
    response = await get_response(request)
  File "/usr/local/lib/python3.10/site-packages/django/core/handlers/base.py", line 253, in _get_response_async
    response = await wrapped_callback(
  File "/usr/local/lib/python3.10/site-packages/asgiref/sync.py", line 468, in __call__
    ret = await asyncio.shield(exec_coro)
  File "/usr/local/lib/python3.10/site-packages/asgiref/current_thread_executor.py", line 40, in run
    result = self.fn(*self.args, **self.kwargs)
  File "/usr/local/lib/python3.10/site-packages/asgiref/sync.py", line 522, in thread_handler
    return func(*args, **kwargs)
  File "/usr/local/lib/python3.10/site-packages/django/views/decorators/csrf.py", line 56, in wrapper_view
    return view_func(*args, **kwargs)
  File "/app/./tournament/views.py", line 220, in finish_match
    create_matches(tournament, winners, round_number=current_round + 1)
  File "/app/./tournament/views.py", line 91, in create_matches
    create_matches(tournament, next_round_qualified, round_number + 1)
  File "/app/./tournament/views.py", line 91, in create_matches
    create_matches(tournament, next_round_qualified, round_number + 1)
  File "/app/./tournament/views.py", line 91, in create_matches
    create_matches(tournament, next_round_qualified, round_number + 1)
  [Previous line repeated 971 more times]
  File "/app/./tournament/views.py", line 74, in create_matches
    while i < len(players):
RecursionError: maximum recursion depth exceeded while calling a Python object
ERROR 2025-03-29 17:04:35,772 log 1 140614750448440 Internal Server Error: /tournament/11/match/23/finish/
Traceback (most recent call last):
  File "/usr/local/lib/python3.10/site-packages/django/db/backends/utils.py", line 89, in _execute
    return self.cursor.execute(sql, params)
psycopg2.errors.NotNullViolation: null value in column "player2_id" of relation "tournament_match" violates not-null constraint
DETAIL:  Failing row contains (25, 2, t, 41, null, 11, 41).


The above exception was the direct cause of the following exception:

Traceback (most recent call last):
  File "/usr/local/lib/python3.10/site-packages/asgiref/sync.py", line 518, in thread_handler
    raise exc_info[1]
  File "/usr/local/lib/python3.10/site-packages/django/core/handlers/exception.py", line 42, in inner
    response = await get_response(request)
  File "/usr/local/lib/python3.10/site-packages/django/core/handlers/base.py", line 253, in _get_response_async
    response = await wrapped_callback(
  File "/usr/local/lib/python3.10/site-packages/asgiref/sync.py", line 468, in __call__
    ret = await asyncio.shield(exec_coro)
  File "/usr/local/lib/python3.10/site-packages/asgiref/current_thread_executor.py", line 40, in run
    result = self.fn(*self.args, **self.kwargs)
  File "/usr/local/lib/python3.10/site-packages/asgiref/sync.py", line 522, in thread_handler
    return func(*args, **kwargs)
  File "/usr/local/lib/python3.10/site-packages/django/views/decorators/csrf.py", line 56, in wrapper_view
    return view_func(*args, **kwargs)
  File "/app/./tournament/views.py", line 230, in finish_match
    create_matches(tournament, winners, round_number=current_round + 1)
  File "/app/./tournament/views.py", line 86, in create_matches
    match = Match.objects.create(
  File "/usr/local/lib/python3.10/site-packages/django/db/models/manager.py", line 87, in manager_method
    return getattr(self.get_queryset(), name)(*args, **kwargs)
  File "/usr/local/lib/python3.10/site-packages/django/db/models/query.py", line 658, in create
    obj.save(force_insert=True, using=self.db)
  File "/usr/local/lib/python3.10/site-packages/django/db/models/base.py", line 814, in save
    self.save_base(
  File "/usr/local/lib/python3.10/site-packages/django/db/models/base.py", line 877, in save_base
    updated = self._save_table(
  File "/usr/local/lib/python3.10/site-packages/django/db/models/base.py", line 1020, in _save_table
    results = self._do_insert(
  File "/usr/local/lib/python3.10/site-packages/django/db/models/base.py", line 1061, in _do_insert
    return manager._insert(
  File "/usr/local/lib/python3.10/site-packages/django/db/models/manager.py", line 87, in manager_method
    return getattr(self.get_queryset(), name)(*args, **kwargs)
  File "/usr/local/lib/python3.10/site-packages/django/db/models/query.py", line 1805, in _insert
    return query.get_compiler(using=using).execute_sql(returning_fields)
  File "/usr/local/lib/python3.10/site-packages/django/db/models/sql/compiler.py", line 1820, in execute_sql
    cursor.execute(sql, params)
  File "/usr/local/lib/python3.10/site-packages/django/db/backends/utils.py", line 102, in execute
    return super().execute(sql, params)
  File "/usr/local/lib/python3.10/site-packages/django/db/backends/utils.py", line 67, in execute
    return self._execute_with_wrappers(
  File "/usr/local/lib/python3.10/site-packages/django/db/backends/utils.py", line 80, in _execute_with_wrappers
    return executor(sql, params, many, context)
  File "/usr/local/lib/python3.10/site-packages/django/db/backends/utils.py", line 84, in _execute
    with self.db.wrap_database_errors:
  File "/usr/local/lib/python3.10/site-packages/django/db/utils.py", line 91, in __exit__
    raise dj_exc_value.with_traceback(traceback) from exc_value
  File "/usr/local/lib/python3.10/site-packages/django/db/backends/utils.py", line 89, in _execute
    return self.cursor.execute(sql, params)
django.db.utils.IntegrityError: null value in column "player2_id" of relation "tournament_match" violates not-null constraint
DETAIL:  Failing row contains (25, 2, t, 41, null, 11, 41).

ERROR 2025-03-29 17:07:30,263 log 1 140170802035512 Internal Server Error: /tournament/12/match/28/finish/
Traceback (most recent call last):
  File "/usr/local/lib/python3.10/site-packages/asgiref/sync.py", line 518, in thread_handler
    raise exc_info[1]
  File "/usr/local/lib/python3.10/site-packages/django/core/handlers/exception.py", line 42, in inner
    response = await get_response(request)
  File "/usr/local/lib/python3.10/site-packages/django/core/handlers/base.py", line 253, in _get_response_async
    response = await wrapped_callback(
  File "/usr/local/lib/python3.10/site-packages/asgiref/sync.py", line 468, in __call__
    ret = await asyncio.shield(exec_coro)
  File "/usr/local/lib/python3.10/site-packages/asgiref/current_thread_executor.py", line 40, in run
    result = self.fn(*self.args, **self.kwargs)
  File "/usr/local/lib/python3.10/site-packages/asgiref/sync.py", line 522, in thread_handler
    return func(*args, **kwargs)
  File "/usr/local/lib/python3.10/site-packages/django/views/decorators/csrf.py", line 56, in wrapper_view
    return view_func(*args, **kwargs)
  File "/app/./tournament/views.py", line 234, in finish_match
    create_matches(tournament, winners, round_number=current_round + 1)
  File "/app/./tournament/views.py", line 103, in create_matches
    matches += create_matches(tournament, next_round_qualified, round_number + 1)
  File "/app/./tournament/views.py", line 103, in create_matches
    matches += create_matches(tournament, next_round_qualified, round_number + 1)
  File "/app/./tournament/views.py", line 103, in create_matches
    matches += create_matches(tournament, next_round_qualified, round_number + 1)
  [Previous line repeated 946 more times]
  File "/app/./tournament/views.py", line 86, in create_matches
    bye_player, _ = Player.objects.get_or_create(
  File "/usr/local/lib/python3.10/site-packages/django/db/models/manager.py", line 87, in manager_method
    return getattr(self.get_queryset(), name)(*args, **kwargs)
  File "/usr/local/lib/python3.10/site-packages/django/db/models/query.py", line 916, in get_or_create
    return self.get(**kwargs), False
  File "/usr/local/lib/python3.10/site-packages/django/db/models/query.py", line 633, in get
    num = len(clone)
  File "/usr/local/lib/python3.10/site-packages/django/db/models/query.py", line 380, in __len__
    self._fetch_all()
  File "/usr/local/lib/python3.10/site-packages/django/db/models/query.py", line 1881, in _fetch_all
    self._result_cache = list(self._iterable_class(self))
  File "/usr/local/lib/python3.10/site-packages/django/db/models/query.py", line 91, in __iter__
    results = compiler.execute_sql(
  File "/usr/local/lib/python3.10/site-packages/django/db/models/sql/compiler.py", line 1547, in execute_sql
    sql, params = self.as_sql()
  File "/usr/local/lib/python3.10/site-packages/django/db/models/sql/compiler.py", line 734, in as_sql
    extra_select, order_by, group_by = self.pre_sql_setup(
  File "/usr/local/lib/python3.10/site-packages/django/db/models/sql/compiler.py", line 85, in pre_sql_setup
    order_by = self.get_order_by()
  File "/usr/local/lib/python3.10/site-packages/django/db/models/sql/compiler.py", line 457, in get_order_by
    for expr, is_ref in self._order_by_pairs():
  File "/usr/local/lib/python3.10/site-packages/django/db/models/sql/compiler.py", line 339, in _order_by_pairs
    selected_exprs[expr] = pos_expr
  File "/usr/local/lib/python3.10/site-packages/django/db/models/expressions.py", line 502, in __hash__
    return hash(self.identity)
  File "/usr/local/lib/python3.10/site-packages/django/utils/functional.py", line 57, in __get__
    res = instance.__dict__[self.name] = self.func(instance)
  File "/usr/local/lib/python3.10/site-packages/django/db/models/expressions.py", line 479, in identity
    constructor_signature = inspect.signature(self.__init__)
  File "/usr/local/lib/python3.10/inspect.py", line 3254, in signature
    return Signature.from_callable(obj, follow_wrapped=follow_wrapped,
  File "/usr/local/lib/python3.10/inspect.py", line 3002, in from_callable
    return _signature_from_callable(obj, sigcls=cls,
  File "/usr/local/lib/python3.10/inspect.py", line 2401, in _signature_from_callable
    sig = _get_signature_of(obj.__func__)
  File "/usr/local/lib/python3.10/inspect.py", line 2463, in _signature_from_callable
    return _signature_from_function(sigcls, obj,
  File "/usr/local/lib/python3.10/inspect.py", line 2325, in _signature_from_function
    parameters.append(Parameter(name, annotation=annotation,
  File "/usr/local/lib/python3.10/inspect.py", line 2639, in __init__
    self._kind = _ParameterKind(kind)
  File "/usr/local/lib/python3.10/enum.py", line 385, in __call__
    return cls.__new__(cls, value)
RecursionError: maximum recursion depth exceeded while calling a Python object
ERROR 2025-03-29 17:16:24,178 log 1 139881516145464 Internal Server Error: /tournament/14/match/988/finish/
Traceback (most recent call last):
  File "/usr/local/lib/python3.10/site-packages/asgiref/sync.py", line 518, in thread_handler
    raise exc_info[1]
  File "/usr/local/lib/python3.10/site-packages/django/core/handlers/exception.py", line 42, in inner
    response = await get_response(request)
  File "/usr/local/lib/python3.10/site-packages/django/core/handlers/base.py", line 265, in _get_response_async
    self.check_response(response, callback)
  File "/usr/local/lib/python3.10/site-packages/django/core/handlers/base.py", line 332, in check_response
    raise ValueError(
ValueError: The view tournament.views.finish_match didn't return an HttpResponse object. It returned None instead.
ERROR 2025-03-29 17:16:28,167 log 1 139881516145464 Internal Server Error: /tournament/14/match/989/finish/
Traceback (most recent call last):
  File "/usr/local/lib/python3.10/site-packages/asgiref/sync.py", line 518, in thread_handler
    raise exc_info[1]
  File "/usr/local/lib/python3.10/site-packages/django/core/handlers/exception.py", line 42, in inner
    response = await get_response(request)
  File "/usr/local/lib/python3.10/site-packages/django/core/handlers/base.py", line 265, in _get_response_async
    self.check_response(response, callback)
  File "/usr/local/lib/python3.10/site-packages/django/core/handlers/base.py", line 332, in check_response
    raise ValueError(
ValueError: The view tournament.views.finish_match didn't return an HttpResponse object. It returned None instead.
WARNING 2025-03-29 17:46:38,237 log 1 140708212755256 Unauthorized: /api/game_settings/
WARNING 2025-03-29 17:46:38,238 log 1 140708211694392 Unauthorized: /api/game_settings/match_history/list/
WARNING 2025-03-29 17:53:58,198 log 1 140310278527800 Unauthorized: /api/game_settings/
WARNING 2025-03-29 17:53:58,203 log 1 140310278527800 Unauthorized: /api/game_settings/match_history/list/
WARNING 2025-03-29 17:55:20,273 log 1 140310278527800 Unauthorized: /api/game_settings/
WARNING 2025-03-29 17:55:20,278 log 1 140310278527800 Unauthorized: /api/game_settings/match_history/list/
